Workbook

Sheet README
A1: RU Relief - demo dataset
A2: Built 2026-10-10 for HackRU. Rutgers-New Brunswick only: College Avenue, Busch, Livingston, Cook/Douglass.
A4: READ THIS FIRST
A5: REAL | B5: Location names, hours, swipe policy ($10 value, 3/day), RU Express acceptance, health-center and nurse-line contacts. Checked against Rutgers pages on 2026-10-10 (see Sources).
A6: SIMULATED | B6: ALL inventory, confidence levels, reports, reservations, pickup codes. They describe a PROPOSED campus health-supply program.
A7: NOT TRUE TODAY | B7: No listed location is known to sell medicine, and meal swipes cannot buy medicine as far as I could verify. Never present this data as Rutgers' real stock. Label it in the demo.
A8: Known gaps | B8: 1) Cook Cafe: location and hours unverified (missing from the current Rutgers Dining hours page) and no coordinates. 2) Coordinates are approximate (Henry's Diner and Woody's embeds are zoomed out). 3) Weekend hours for Cafe West, Kilmer's, Henry's, Harvest, Woody's and Douglass are not listed by Rutgers (left blank). 4) Product caution text is general OTC knowledge, not reviewed by a pharmacist.
A9: Left out on purpose | B9: Condoms and emergency contraception (RU Wrapped already covers them; easy to add). Pharmacies and off-campus stores (your scope). Dorm lists (privacy). Stockout history (you chose none). Delivery and couriers (you faded them). Real bus times (use Rutgers bus data/Google Maps API).
A10: How to demo time passing | B10: Edit Config!B2 (DEMO_NOW). Reports older than their validity turn 'Stale report', reservations auto-expire, and Admin_Summary updates.
A11: Size | B11: 8 locations, 28 products, 224 inventory rows (144 proposed, rest 'Not stocked in proposal'), 20 reports, 10 reservations, 12 scenarios.
A12: Colors | B12: Blue text = input values. Black = formulas. Green = lookups from another sheet. Yellow fill = edit me. Header row is row 1 on data sheets so you can import them straight into SQLite/Flask.
A14: Tabs
A15: Config | B15: Demo clock, validity windows, reservation length, geofence radius, swipe policy numbers, suggested ranking weights.
A16: Locations | B16: 8 real retail locations with hours and swipe info.
A17: Products | B17: 28 branded OTC items with plain-language definitions.
A18: Inventory | B18: 224 simulated stock records with confidence and expiry formulas.
A19: Verification_Reports | B19: 20 sample reports with geofence and photo review outcomes.
A20: Reservations | B20: 10 sample holds with 75-minute auto-expiry.
A21: Distance_Matrix | B21: Straight-line distance and rough walk time between locations.
A22: Admin_Summary | B22: Counts by zone, restock alerts, stale reports, reservation states.
A23: Scenarios | B23: 12 demo scripts tied to specific records.
A24: Health_Escalation | B24: Real Rutgers contacts for the app's 'get real help' path.
A25: Sources | B25: Where each real fact came from.
A26: Codebook | B26: Every field: meaning, allowed values, and whether it is verified, simulated or derived.

Sheet Config
A1: parameter | B1: value | C1: unit | D1: basis | E1: status | G1: Yellow cells with blue text are the inputs to edit. Everything else recalculates.
A2: DEMO_NOW (simulated current time) | B2: 46308.625 | C2: datetime | D2: Fixed demo clock (a Tuesday, 3:00 PM). Change it to watch reports go stale and reservations expire. | E2: Demo setting
A3: student_report_validity_min | B3: 60 | C3: minutes | D3: Student report stays trusted for 60 minutes (value recommended in the ChatGPT planning notes; no objection recorded). | E3: Proposed default
A4: staff_report_validity_min | B4: 240 | C4: minutes | D4: Staff report stays trusted for 4 hours (same source). | E4: Proposed default
A5: reservation_minutes | B5: 75 | C5: minutes | D5: You asked for 60-90 minutes; 75 is the midpoint. | E5: Proposed default
A6: geofence_radius_m | B6: 150 | C6: meters | D6: Distance within which a student's phone location must be to confirm a report. My assumption; tune with real GPS error. | E6: Assumption
A7: meal_swipe_retail_value_usd | B7: 10 | C7: USD | D7: Rutgers retail policy: a meal swipe at retail is a $10 meal value. | E7: Verified (food.rutgers.edu/policies/retail)
A8: retail_swipe_daily_limit | B8: 3 | C8: swipes/day | D8: Rutgers retail policy: 3 swipes/day across retail and dining-hall takeout. | E8: Verified (same page)
A9: walking_speed_kmh | B9: 4.8 | C9: km/h | D9: Typical walking pace used for the rough walk-time estimate. Replace with Google Maps API times. | E9: Assumption
A10: route_detour_factor | B10: 1.3 | C10: multiplier | D10: Straight-line distance x 1.3 approximates a walking route. Replace with Google Maps API. | E10: Assumption
A11: weight_availability | B11: 0.4 | C11: weight | D11: Suggested ranking weights for the app (not used by formulas in this workbook). | E11: Suggested default
A12: weight_confidence | B12: 0.25 | C12: weight | D12: Same. | E12: Suggested default
A13: weight_proximity | B13: 0.2 | C13: weight | D13: Same. | E13: Suggested default
... A15: stale_penalty | B15: 0.2 | C15: score deduction | D15: Subtract from a result's score when its report is stale. | E15: Suggested default

Sheet Locations
A1: location_id | B1: location_name | C1: campus_zone | D1: site_description | E1: latitude | F1: longitude | G1: coordinate_note | H1: location_type | I1: meal_swipe_eligible_today | J1: ru_express_accepted_today | K1: swipe_notes | L1: hours_basis | M1: mon_thu_open | N1: mon_thu_close | O1: fri_open | P1: fri_close | Q1: sat_open | R1: sat_close | S1: sun_open | T1: sun_close | U1: proposed_health_section | V1: reservation_supported | W1: staff_verification_supported | X1: student_verification_supported | Y1: product_tier | Z1: verification_notes
A2: L01 | B2: The Atrium | C2: College Avenue | D2: College Avenue Student Center (lower level), 126 College Ave | E2: 40.502873 | F2: -74.45482 | G2: Google Maps embed on Rutgers Dining page (approx.) | H2: Retail food court | I2: Yes | J2: Yes | K2: Up to 3 swipes before 9 PM that do not count toward the daily retail limit; after 9 PM swipes count toward the 3/day retail limit. | L2: Dine-in and takeout share the same hours. | M2: 07:00 | N2: 24:00 | O2: 07:00 | P2: 21:00 | Q2: 09:30 | R2: 20:00 | S2: 09:30 | T2: 20:00 | U2: Proposed (not available today) | V2: Prototype | W2: Yes (prototype) | X2: Yes (prototype) | Y2: Full | Z2: Hours and swipe policy checked on food.rutgers.edu 2026-10-10.
A3: L02 | B3: Cafe West | C3: College Avenue | D3: Academic Building west wing, College Ave campus | E3: 40.502116 | F3: -74.448503 | G3: Google Maps embed on Rutgers Dining page (approx.) | H3: Cafe | I3: Yes | J3: Yes | K3: Retail swipe: $10 meal value, 3/day across retail and dining-hall takeout. | L3: Weekend hours not listed by Rutgers Dining (a Daily Targum editorial says closed on weekends). | M3: 09:00 | N3: 23:00 | O3: 09:00 | P3: 20:00 | U3: Proposed (not available today) | V3: Prototype | W3: Yes (prototype) | X3: Yes (prototype) | Y3: Full | Z3: Building description comes from a Daily Targum editorial, not from Rutgers Dining.
A4: L03 | B4: Kilmer's Market | C4: Livingston | D4: Livingston campus (exact building not stated on Rutgers Dining page) | E4: 40.525739 | F4: -74.438777 | G4: Google Maps embed on Rutgers Dining page (approx.) | H4: Retail market | I4: Yes | J4: Yes | K4: Retail swipe: $10 meal value, 3/day. Rutgers says swipes are accepted all day. | L4: Weekend hours not listed by Rutgers Dining. | M4: 11:00 | N4: 23:00 | O4: 11:00 | P4: 21:00 | U4: Proposed (not available today) | V4: Prototype | W4: Yes (prototype) | X4: Yes (prototype) | Y4: Full | Z4: Rutgers Dining says Kilmer's sells toiletries, school supplies and grocery items today; it does not list medicine. Online ordering recommended by Rutgers.
A5: L04 | B5: Henry's Diner | C5: Livingston | D5: The Plaza at Livingston | E5: 40.528617 | F5: -74.445004 | G5: Google Maps embed on Rutgers Dining page (zoomed out; lower precision) | H5: Diner | I5: Yes | J5: Yes | K5: Retail swipe: $10 meal value, 3/day. Rutgers says swipes accepted at all times. | L5: Takeout window shown (10:00-18:00 weekdays); dine-in is 11:00-18:00. | M5: 10:00 | N5: 18:00 | O5: 10:00 | P5: 18:00 | U5: Proposed (not available today) | V5: Prototype | W5: Yes (prototype) | X5: Yes (prototype) | Y5: Core | Z5: Weekdays only.
A6: L05 | B6: Harvest Juice Bar | C6: Busch | D6: Busch Student Center, 604 Bartholomew Rd | E6: 40.523332 | F6: -74.460857 | G6: Google Maps embed on Rutgers Dining page (approx.) | H6: Juice bar / snacks | I6: Yes | J6: Yes | K6: Retail swipe: $10 meal value, 3/day. | L6: Weekdays only. | M6: 10:00 | N6: 15:30 | O6: 10:00 | P6: 15:30 | U6: Proposed (not available today) | V6: Prototype | W6: Yes (prototype) | X6: Yes (prototype) | Y6: Core | Z6: Small counter; the least realistic site for a shelf (kept because it was in the agreed location list).
A7: L06 | B7: Woody's Cafe | C7: Busch | D7: Kessler Teaching Building | E7: 40.524487 | F7: -74.468668 | G7: Google Maps embed on Rutgers Dining page (zoomed out; lower precision) | H7: Cafe | I7: Yes | J7: Yes | K7: Retail swipe: $10 meal value, 3/day. | L7: Weekdays only. | M7: 07:30 | N7: 18:00 | O7: 07:30 | P7: 18:00 | U7: Proposed (not available today) | V7: Prototype | W7: Yes (prototype) | X7: Yes (prototype) | Y7: Core | Z7: Reddit users (per the ChatGPT research notes) mentioned limited supplies here; not verified by this workbook.
A8: L07 | B8: Cook Cafe | C8: Cook/Douglass | D8: UNVERIFIED: assumed Cook Student Center, 59 Biel Rd | G8: NO COORDINATES - geocode with Google Maps API once the location is confirmed | H8: Cafe | I8: Yes | J8: Yes | K8: Listed as meal-swipe eligible on the Rutgers retail policy page and as accepting RU Express (Feb 2026 list). | L8: UNVERIFIED: Cook Cafe is not on the current Rutgers Dining hours page. Cook Student Center itself is open 12:00-24:00 daily (verified). | U8: Proposed (not available today) | V8: Prototype | W8: Yes (prototype) | X8: Yes (prototype) | Y8: Core | Z8: Conflicting sources: retail policy page and RU Express list include it; the hours page does not. Confirm it is still operating before the demo.
A9: L08 | B9: Douglass Cafe | C9: Cook/Douglass | D9: Douglass Student Center, 100 George St | E9: 40.484728 | F9: -74.436627 | G9: Google Maps embed on Rutgers Dining page (Douglass Student Center) | H9: Cafe | I9: Yes | J9: Yes | K9: Retail swipe: $10 meal value, 3/day. | L9: Weekend hours not listed by Rutgers Dining. | M9: 08:00 | N9: 21:00 | O9: 08:00 | P9: 16:00 | U9: Proposed (not available today) | V9: Prototype | W9: Yes (prototype) | X9: Yes (prototype) | Y9: Core | Z9: Hours checked on food.rutgers.edu 2026-10-10.

Sheet Products
A1: product_id | B1: product_name | C1: category | D1: active_ingredient_or_type | E1: simple_definition | F1: typical_use | G1: label_caution | H1: product_tier | I1: quantity_limit_per_transaction | J1: requires_staff_assistance | K1: retail_swipe_status | L1: data_basis
A2: P01 | B2: Tylenol Extra Strength | C2: Pain & fever | D2: Acetaminophen | E2: Pain reliever and fever reducer | F2: Headaches, body aches, and fever | G2: Liver warning: do not combine with other acetaminophen products. | H2: Core | I2: 1 package | J2: No | K2: proposed_pending_approval | L2: Standard OTC label basics; confirm against the current package and a pharmacist before real use.
A3: P02 | B3: Advil | C3: Pain & fever | D3: Ibuprofen (NSAID) | E3: Pain reliever and fever reducer | F3: Headaches, muscle pain, menstrual cramps, and fever | G3: Can irritate the stomach. Ask a pharmacist if you take blood thinners or have stomach, kidney, or heart conditions. | H3: Core | I3: 1 package | J3: No | K3: proposed_pending_approval | L3: Standard OTC label basics; confirm against the current package and a pharmacist before real use.
A4: P03 | B4: Aleve | C4: Pain & fever | D4: Naproxen sodium (NSAID) | E4: Longer-lasting NSAID pain reliever | F4: Aches, cramps, and minor joint pain | G4: Can irritate the stomach. Ask a pharmacist if you take blood thinners or have stomach, kidney, or heart conditions. | H4: Extended | I4: 1 package | J4: No | K4: proposed_pending_approval | L4: Standard OTC label basics; confirm against the current package and a pharmacist before real use.
A5: P04 | B5: Excedrin Migraine | C5: Pain & fever | D5: Acetaminophen + aspirin + caffeine | E5: Combination headache reliever | F5: Headaches, including migraine | G5: Contains aspirin and caffeine. Check the label for age limits and allergies. | H5: Extended | I5: 1 package | J5: No | K5: proposed_pending_approval | L5: Standard OTC label basics; confirm against the current package and a pharmacist before real use.
A6: P05 | B6: Halls Mentho-Lyptus | C6: Cold & cough | D6: Menthol throat lozenge | E6: Throat lozenge (cough drop) | F6: Temporary relief of a sore or irritated throat and cough | G6: Follow label directions. | H6: Core | I6: 2 bags | J6: No | K6: proposed_pending_approval | L6: Standard OTC label basics; confirm against the current package and a pharmacist before real use.
A7: P06 | B7: Ricola Original Natural Herb | C7: Cold & cough | D7: Herbal throat lozenge | E7: Herbal throat lozenge (cough drop) | F7: Soothing a scratchy throat | G7: Follow label directions. | H7: Extended | I7: 2 bags | J7: No | K7: proposed_pending_approval | L7: Standard OTC label basics; confirm against the current package and a pharmacist before real use.
A8: P07 | B8: Chloraseptic Sore Throat Spray | C8: Cold & cough | D8: Phenol (oral anesthetic) spray | E8: Numbing throat spray | F8: Short-term sore throat pain relief | G8: Follow label directions. | H8: Extended | I8: 1 bottle | J8: No | K8: proposed_pending_approval | L8: Standard OTC label basics; confirm against the current package and a pharmacist before real use.
A9: P08 | B9: Mucinex | C9: Cold & cough | D9: Guaifenesin (expectorant) | E9: Expectorant that helps loosen mucus | F9: Chest congestion and mucus | G9: Check the label if you take other cold products with the same ingredient. | H9: Core | I9: 1 package | J9: No | K9: proposed_pending_approval | L9: Standard OTC label basics; confirm against the current package and a pharmacist before real use.
A10: P09 | B10: Robitussin DM | C10: Cold & cough | D10: Dextromethorphan + guaifenesin | E10: Cough suppressant plus expectorant | F10: Coughing and chest congestion | G10: Do not combine with other cough or cold products that share these ingredients. | H10: Extended | I10: 1 bottle | J10: No | K10: proposed_pending_approval | L10: Standard OTC label basics; confirm against the current package and a pharmacist before real use.
A11: P10 | B11: Simply Saline Nasal Mist | C11: Cold & cough | D11: Sodium chloride nasal spray | E11: Saltwater nasal spray | F11: Dry or stuffy nose | G11: Follow label directions. | H11: Extended | I11: 1 bottle | J11: No | K11: proposed_pending_approval | L11: Standard OTC label basics; confirm against the current package and a pharmacist before real use.
A12: P11 | B12: Claritin | C12: Allergy | D12: Loratadine | E12: Antihistamine allergy medicine (generally less drowsy) | F12: Sneezing, runny nose, and itchy eyes | G12: Follow label directions; ask a pharmacist if you take other medicines. | H12: Core | I12: 1 package | J12: No | K12: proposed_pending_approval | L12: Standard OTC label basics; confirm against the current package and a pharmacist before real use.
... A29: P28 | B29: Disposable face masks (brand varies) | C29: Menstrual & hygiene | D29: Device | E29: Face coverings | F29: Reducing exposure to respiratory droplets | G29: Follow label directions. | H29: Extended | I29: 1 pack | J29: No | K29: proposed_pending_approval | L29: Standard OTC label basics; confirm against the current package and a pharmacist before real use.

Sheet Inventory
A1: inventory_id | B1: location_id | C1: location_name | D1: campus_zone | E1: product_id | F1: product_name | G1: category | H1: proposed_to_stock | I1: availability_status | J1: quantity_band | K1: reported_confidence | L1: last_verified | M1: minutes_since_verified | N1: validity_minutes | O1: effective_confidence | P1: reservable | Q1: retail_swipe_status | R1: payment_options | S1: quantity_limit | T1: reservation_minutes | U1: requires_staff_assistance | V1: data_label
A2: INV-001 | B2: L01 | C2: =INDEX(Locations!$B$2:$B$9,MATCH($B2,Locations!$A$2:$A$9,0)) -> The Atrium | D2: =INDEX(Locations!$C$2:$C$9,MATCH($B2,Locations!$A$2:$A$9,0)) -> College Avenue | E2: P01 | F2: =INDEX(Products!$B$2:$B$29,MATCH($E2,Products!$A$2:$A$29,0)) -> Tylenol Extra Strength | G2: =INDEX(Products!$C$2:$C$29,MATCH($E2,Products!$A$2:$A$29,0)) -> Pain & fever | H2: Yes | I2: Available | J2: =IF(H2="No","-",IF(I2="Available","Good supply",IF(I2="Low stock","Few left",IF(I2="Out of stock","None",IF(I2="Temporarily unavailable","Unavailable","Unknown"))))) -> Good supply | K2: Staff verified | L2: 46308.594 | M2: =IF(L2="","",ROUND((Config!$B$2-L2)*1440,0)) -> 45 | N2: =IF(K2="Staff verified",Config!$B$4,IF(OR(K2="Authorized student verified",K2="Multiple student reports",K2="Single student report"),Config!$B$3,"")) -> 240 | O2: =IF(H2="No","n/a",IF(L2="","Unverified Data",IF(M2>N2,"Stale report",K2))) -> Staff verified | P2: =IF(AND(H2="Yes",OR(I2="Available",I2="Low stock")),IF(O2="Stale report","Verify first","Yes"),"No") -> Yes | Q2: =IF(H2="Yes","proposed_pending_approval","n/a") -> proposed_pending_approval | R2: =IF(H2="Yes","Retail swipe (proposed) / RU Express / Cash or card","n/a") -> Retail swipe (proposed) / RU Express / Cash or card | S2: =INDEX(Products!$I$2:$I$29,MATCH($E2,Products!$A$2:$A$29,0)) -> 1 package | T2: =IF(H2="Yes",Config!$B$5,"") -> 75 | U2: =INDEX(Products!$J$2:$J$29,MATCH($E2,Products!$A$2:$A$29,0)) -> No | V2: SIMULATED - proposed campus health-supply program
A3: INV-002 | B3: L01 | C3: =INDEX(Locations!$B$2:$B$9,MATCH($B3,Locations!$A$2:$A$9,0)) -> The Atrium | D3: =INDEX(Locations!$C$2:$C$9,MATCH($B3,Locations!$A$2:$A$9,0)) -> College Avenue | E3: P02 | F3: =INDEX(Products!$B$2:$B$29,MATCH($E3,Products!$A$2:$A$29,0)) -> Advil | G3: =INDEX(Products!$C$2:$C$29,MATCH($E3,Products!$A$2:$A$29,0)) -> Pain & fever | H3: Yes | I3: Out of stock | J3: =IF(H3="No","-",IF(I3="Available","Good supply",IF(I3="Low stock","Few left",IF(I3="Out of stock","None",IF(I3="Temporarily unavailable","Unavailable","Unknown"))))) -> None | K3: Verified student report | L3: 46308.617 | M3: =IF(L3="","",ROUND((Config!$B$2-L3)*1440,0)) -> 12 | N3: =IF(K3="Staff verified",Config!$B$4,IF(OR(K3="Authorized student verified",K3="Multiple student reports",K3="Single student report"),Config!$B$3,"")) | O3: =IF(H3="No","n/a",IF(L3="","Unverified Data",IF(M3>N3,"Stale report",K3))) -> Verified student report | P3: =IF(AND(H3="Yes",OR(I3="Available",I3="Low stock")),IF(O3="Stale report","Verify first","Yes"),"No") -> No | Q3: =IF(H3="Yes","proposed_pending_approval","n/a") -> proposed_pending_approval | R3: =IF(H3="Yes","Retail swipe (proposed) / RU Express / Cash or card","n/a") -> Retail swipe (proposed) / RU Express / Cash or card | S3: =INDEX(Products!$I$2:$I$29,MATCH($E3,Products!$A$2:$A$29,0)) -> 1 package | T3: =IF(H3="Yes",Config!$B$5,"") -> 75 | U3: =INDEX(Products!$J$2:$J$29,MATCH($E3,Products!$A$2:$A$29,0)) -> No | V3: SIMULATED - proposed campus health-supply program
A4: INV-003 | B4: L01 | C4: =INDEX(Locations!$B$2:$B$9,MATCH($B4,Locations!$A$2:$A$9,0)) -> The Atrium | D4: =INDEX(Locations!$C$2:$C$9,MATCH($B4,Locations!$A$2:$A$9,0)) -> College Avenue | E4: P03 | F4: =INDEX(Products!$B$2:$B$29,MATCH($E4,Products!$A$2:$A$29,0)) -> Aleve | G4: =INDEX(Products!$C$2:$C$29,MATCH($E4,Products!$A$2:$A$29,0)) -> Pain & fever | H4: Yes | I4: Available | J4: =IF(H4="No","-",IF(I4="Available","Good supply",IF(I4="Low stock","Few left",IF(I4="Out of stock","None",IF(I4="Temporarily unavailable","Unavailable","Unknown"))))) -> Good supply | K4: Verified student report | L4: 46308.61 | M4: =IF(L4="","",ROUND((Config!$B$2-L4)*1440,0)) -> 21 | N4: =IF(K4="Staff verified",Config!$B$4,IF(OR(K4="Authorized student verified",K4="Multiple student reports",K4="Single student report"),Config!$B$3,"")) | O4: =IF(H4="No","n/a",IF(L4="","Unverified Data",IF(M4>N4,"Stale report",K4))) -> Verified student report | P4: =IF(AND(H4="Yes",OR(I4="Available",I4="Low stock")),IF(O4="Stale report","Verify first","Yes"),"No") -> Yes | Q4: =IF(H4="Yes","proposed_pending_approval","n/a") -> proposed_pending_approval | R4: =IF(H4="Yes","Retail swipe (proposed) / RU Express / Cash or card","n/a") -> Retail swipe (proposed) / RU Express / Cash or card | S4: =INDEX(Products!$I$2:$I$29,MATCH($E4,Products!$A$2:$A$29,0)) -> 1 package | T4: =IF(H4="Yes",Config!$B$5,"") -> 75 | U4: =INDEX(Products!$J$2:$J$29,MATCH($E4,Products!$A$2:$A$29,0)) -> No | V4: SIMULATED - proposed campus health-supply program
A5: INV-004 | B5: L01 | C5: =INDEX(Locations!$B$2:$B$9,MATCH($B5,Locations!$A$2:$A$9,0)) -> The Atrium | D5: =INDEX(Locations!$C$2:$C$9,MATCH($B5,Locations!$A$2:$A$9,0)) -> College Avenue | E5: P04 | F5: =INDEX(Products!$B$2:$B$29,MATCH($E5,Products!$A$2:$A$29,0)) -> Excedrin Migraine | G5: =INDEX(Products!$C$2:$C$29,MATCH($E5,Products!$A$2:$A$29,0)) -> Pain & fever | H5: Yes | I5: Available | J5: =IF(H5="No","-",IF(I5="Available","Good supply",IF(I5="Low stock","Few left",IF(I5="Out of stock","None",IF(I5="Temporarily unavailable","Unavailable","Unknown"))))) -> Good supply | K5: Verified student report | L5: 46308.614 | M5: =IF(L5="","",ROUND((Config!$B$2-L5)*1440,0)) -> 16 | N5: =IF(K5="Staff verified",Config!$B$4,IF(OR(K5="Authorized student verified",K5="Multiple student reports",K5="Single student report"),Config!$B$3,"")) | O5: =IF(H5="No","n/a",IF(L5="","Unverified Data",IF(M5>N5,"Stale report",K5))) -> Verified student report | P5: =IF(AND(H5="Yes",OR(I5="Available",I5="Low stock")),IF(O5="Stale report","Verify first","Yes"),"No") -> Yes | Q5: =IF(H5="Yes","proposed_pending_approval","n/a") -> proposed_pending_approval | R5: =IF(H5="Yes","Retail swipe (proposed) / RU Express / Cash or card","n/a") -> Retail swipe (proposed) / RU Express / Cash or card | S5: =INDEX(Products!$I$2:$I$29,MATCH($E5,Products!$A$2:$A$29,0)) -> 1 package | T5: =IF(H5="Yes",Config!$B$5,"") -> 75 | U5: =INDEX(Products!$J$2:$J$29,MATCH($E5,Products!$A$2:$A$29,0)) -> No | V5: SIMULATED - proposed campus health-supply program
A6: INV-005 | B6: L01 | C6: =INDEX(Locations!$B$2:$B$9,MATCH($B6,Locations!$A$2:$A$9,0)) -> The Atrium | D6: =INDEX(Locations!$C$2:$C$9,MATCH($B6,Locations!$A$2:$A$9,0)) -> College Avenue | E6: P05 | F6: =INDEX(Products!$B$2:$B$29,MATCH($E6,Products!$A$2:$A$29,0)) -> Halls Mentho-Lyptus | G6: =INDEX(Products!$C$2:$C$29,MATCH($E6,Products!$A$2:$A$29,0)) -> Cold & cough | H6: Yes | I6: Available | J6: =IF(H6="No","-",IF(I6="Available","Good supply",IF(I6="Low stock","Few left",IF(I6="Out of stock","None",IF(I6="Temporarily unavailable","Unavailable","Unknown"))))) -> Good supply | K6: Verified student report | L6: 46308.597 | M6: =IF(L6="","",ROUND((Config!$B$2-L6)*1440,0)) -> 41 | N6: =IF(K6="Staff verified",Config!$B$4,IF(OR(K6="Authorized student verified",K6="Multiple student reports",K6="Single student report"),Config!$B$3,"")) | O6: =IF(H6="No","n/a",IF(L6="","Unverified Data",IF(M6>N6,"Stale report",K6))) -> Verified student report | P6: =IF(AND(H6="Yes",OR(I6="Available",I6="Low stock")),IF(O6="Stale report","Verify first","Yes"),"No") -> Yes | Q6: =IF(H6="Yes","proposed_pending_approval","n/a") -> proposed_pending_approval | R6: =IF(H6="Yes","Retail swipe (proposed) / RU Express / Cash or card","n/a") -> Retail swipe (proposed) / RU Express / Cash or card | S6: =INDEX(Products!$I$2:$I$29,MATCH($E6,Products!$A$2:$A$29,0)) -> 2 bags | T6: =IF(H6="Yes",Config!$B$5,"") -> 75 | U6: =INDEX(Products!$J$2:$J$29,MATCH($E6,Products!$A$2:$A$29,0)) -> No | V6: SIMULATED - proposed campus health-supply program
A7: INV-006 | B7: L01 | C7: =INDEX(Locations!$B$2:$B$9,MATCH($B7,Locations!$A$2:$A$9,0)) -> The Atrium | D7: =INDEX(Locations!$C$2:$C$9,MATCH($B7,Locations!$A$2:$A$9,0)) -> College Avenue | E7: P06 | F7: =INDEX(Products!$B$2:$B$29,MATCH($E7,Products!$A$2:$A$29,0)) -> Ricola Original Natural Herb | G7: =INDEX(Products!$C$2:$C$29,MATCH($E7,Products!$A$2:$A$29,0)) -> Cold & cough | H7: Yes | I7: Available | J7: =IF(H7="No","-",IF(I7="Available","Good supply",IF(I7="Low stock","Few left",IF(I7="Out of stock","None",IF(I7="Temporarily unavailable","Unavailable","Unknown"))))) -> Good supply | K7: Verified student report | L7: 46308.615 | M7: =IF(L7="","",ROUND((Config!$B$2-L7)*1440,0)) -> 15 | N7: =IF(K7="Staff verified",Config!$B$4,IF(OR(K7="Authorized student verified",K7="Multiple student reports",K7="Single student report"),Config!$B$3,"")) | O7: =IF(H7="No","n/a",IF(L7="","Unverified Data",IF(M7>N7,"Stale report",K7))) -> Verified student report | P7: =IF(AND(H7="Yes",OR(I7="Available",I7="Low stock")),IF(O7="Stale report","Verify first","Yes"),"No") -> Yes | Q7: =IF(H7="Yes","proposed_pending_approval","n/a") -> proposed_pending_approval | R7: =IF(H7="Yes","Retail swipe (proposed) / RU Express / Cash or card","n/a") -> Retail swipe (proposed) / RU Express / Cash or card | S7: =INDEX(Products!$I$2:$I$29,MATCH($E7,Products!$A$2:$A$29,0)) -> 2 bags | T7: =IF(H7="Yes",Config!$B$5,"") -> 75 | U7: =INDEX(Products!$J$2:$J$29,MATCH($E7,Products!$A$2:$A$29,0)) -> No | V7: SIMULATED - proposed campus health-supply program
A8: INV-007 | B8: L01 | C8: =INDEX(Locations!$B$2:$B$9,MATCH($B8,Locations!$A$2:$A$9,0)) -> The Atrium | D8: =INDEX(Locations!$C$2:$C$9,MATCH($B8,Locations!$A$2:$A$9,0)) -> College Avenue | E8: P07 | F8: =INDEX(Products!$B$2:$B$29,MATCH($E8,Products!$A$2:$A$29,0)) -> Chloraseptic Sore Throat Spray | G8: =INDEX(Products!$C$2:$C$29,MATCH($E8,Products!$A$2:$A$29,0)) -> Cold & cough | H8: Yes | I8: Available | J8: =IF(H8="No","-",IF(I8="Available","Good supply",IF(I8="Low stock","Few left",IF(I8="Out of stock","None",IF(I8="Temporarily unavailable","Unavailable","Unknown"))))) -> Good supply | K8: Staff verified | L8: 46308.602 | M8: =IF(L8="","",ROUND((Config!$B$2-L8)*1440,0)) -> 33 | N8: =IF(K8="Staff verified",Config!$B$4,IF(OR(K8="Authorized student verified",K8="Multiple student reports",K8="Single student report"),Config!$B$3,"")) -> 240 | O8: =IF(H8="No","n/a",IF(L8="","Unverified Data",IF(M8>N8,"Stale report",K8))) -> Staff verified | P8: =IF(AND(H8="Yes",OR(I8="Available",I8="Low stock")),IF(O8="Stale report","Verify first","Yes"),"No") -> Yes | Q8: =IF(H8="Yes","proposed_pending_approval","n/a") -> proposed_pending_approval | R8: =IF(H8="Yes","Retail swipe (proposed) / RU Express / Cash or card","n/a") -> Retail swipe (proposed) / RU Express / Cash or card | S8: =INDEX(Products!$I$2:$I$29,MATCH($E8,Products!$A$2:$A$29,0)) -> 1 bottle | T8: =IF(H8="Yes",Config!$B$5,"") -> 75 | U8: =INDEX(Products!$J$2:$J$29,MATCH($E8,Products!$A$2:$A$29,0)) -> No | V8: SIMULATED - proposed campus health-supply program
A9: INV-008 | B9: L01 | C9: =INDEX(Locations!$B$2:$B$9,MATCH($B9,Locations!$A$2:$A$9,0)) -> The Atrium | D9: =INDEX(Locations!$C$2:$C$9,MATCH($B9,Locations!$A$2:$A$9,0)) -> College Avenue | E9: P08 | F9: =INDEX(Products!$B$2:$B$29,MATCH($E9,Products!$A$2:$A$29,0)) -> Mucinex | G9: =INDEX(Products!$C$2:$C$29,MATCH($E9,Products!$A$2:$A$29,0)) -> Cold & cough | H9: Yes | I9: Low stock | J9: =IF(H9="No","-",IF(I9="Available","Good supply",IF(I9="Low stock","Few left",IF(I9="Out of stock","None",IF(I9="Temporarily unavailable","Unavailable","Unknown"))))) -> Few left | K9: Staff verified | L9: 46308.549 | M9: =IF(L9="","",ROUND((Config!$B$2-L9)*1440,0)) -> 110 | N9: =IF(K9="Staff verified",Config!$B$4,IF(OR(K9="Authorized student verified",K9="Multiple student reports",K9="Single student report"),Config!$B$3,"")) -> 240 | O9: =IF(H9="No","n/a",IF(L9="","Unverified Data",IF(M9>N9,"Stale report",K9))) -> Staff verified | P9: =IF(AND(H9="Yes",OR(I9="Available",I9="Low stock")),IF(O9="Stale report","Verify first","Yes"),"No") -> Yes | Q9: =IF(H9="Yes","proposed_pending_approval","n/a") -> proposed_pending_approval | R9: =IF(H9="Yes","Retail swipe (proposed) / RU Express / Cash or card","n/a") -> Retail swipe (proposed) / RU Express / Cash or card | S9: =INDEX(Products!$I$2:$I$29,MATCH($E9,Products!$A$2:$A$29,0)) -> 1 package | T9: =IF(H9="Yes",Config!$B$5,"") -> 75 | U9: =INDEX(Products!$J$2:$J$29,MATCH($E9,Products!$A$2:$A$29,0)) -> No | V9: SIMULATED - proposed campus health-supply program
A10: INV-009 | B10: L01 | C10: =INDEX(Locations!$B$2:$B$9,MATCH($B10,Locations!$A$2:$A$9,0)) -> The Atrium | D10: =INDEX(Locations!$C$2:$C$9,MATCH($B10,Locations!$A$2:$A$9,0)) -> College Avenue | E10: P09 | F10: =INDEX(Products!$B$2:$B$29,MATCH($E10,Products!$A$2:$A$29,0)) -> Robitussin DM | G10: =INDEX(Products!$C$2:$C$29,MATCH($E10,Products!$A$2:$A$29,0)) -> Cold & cough | H10: Yes | I10: Available | J10: =IF(H10="No","-",IF(I10="Available","Good supply",IF(I10="Low stock","Few left",IF(I10="Out of stock","None",IF(I10="Temporarily unavailable","Unavailable","Unknown"))))) -> Good supply | K10: Staff verified | L10: 46308.488 | M10: =IF(L10="","",ROUND((Config!$B$2-L10)*1440,0)) -> 198 | N10: =IF(K10="Staff verified",Config!$B$4,IF(OR(K10="Authorized student verified",K10="Multiple student reports",K10="Single student report"),Config!$B$3,"")) -> 240 | O10: =IF(H10="No","n/a",IF(L10="","Unverified Data",IF(M10>N10,"Stale report",K10))) -> Staff verified | P10: =IF(AND(H10="Yes",OR(I10="Available",I10="Low stock")),IF(O10="Stale report","Verify first","Yes"),"No") -> Yes | Q10: =IF(H10="Yes","proposed_pending_approval","n/a") -> proposed_pending_approval | R10: =IF(H10="Yes","Retail swipe (proposed) / RU Express / Cash or card","n/a") -> Retail swipe (proposed) / RU Express / Cash or card | S10: =INDEX(Products!$I$2:$I$29,MATCH($E10,Products!$A$2:$A$29,0)) -> 1 bottle | T10: =IF(H10="Yes",Config!$B$5,"") -> 75 | U10: =INDEX(Products!$J$2:$J$29,MATCH($E10,Products!$A$2:$A$29,0)) -> No | V10: SIMULATED - proposed campus health-supply program
A11: INV-010 | B11: L01 | C11: =INDEX(Locations!$B$2:$B$9,MATCH($B11,Locations!$A$2:$A$9,0)) -> The Atrium | D11: =INDEX(Locations!$C$2:$C$9,MATCH($B11,Locations!$A$2:$A$9,0)) -> College Avenue | E11: P10 | F11: =INDEX(Products!$B$2:$B$29,MATCH($E11,Products!$A$2:$A$29,0)) -> Simply Saline Nasal Mist | G11: =INDEX(Products!$C$2:$C$29,MATCH($E11,Products!$A$2:$A$29,0)) -> Cold & cough | H11: Yes | I11: Available | J11: =IF(H11="No","-",IF(I11="Available","Good supply",IF(I11="Low stock","Few left",IF(I11="Out of stock","None",IF(I11="Temporarily unavailable","Unavailable","Unknown"))))) -> Good supply | K11: Verified student report | L11: 46308.603 | M11: =IF(L11="","",ROUND((Config!$B$2-L11)*1440,0)) -> 31 | N11: =IF(K11="Staff verified",Config!$B$4,IF(OR(K11="Authorized student verified",K11="Multiple student reports",K11="Single student report"),Config!$B$3,"")) | O11: =IF(H11="No","n/a",IF(L11="","Unverified Data",IF(M11>N11,"Stale report",K11))) -> Verified student report | P11: =IF(AND(H11="Yes",OR(I11="Available",I11="Low stock")),IF(O11="Stale report","Verify first","Yes"),"No") -> Yes | Q11: =IF(H11="Yes","proposed_pending_approval","n/a") -> proposed_pending_approval | R11: =IF(H11="Yes","Retail swipe (proposed) / RU Express / Cash or card","n/a") -> Retail swipe (proposed) / RU Express / Cash or card | S11: =INDEX(Products!$I$2:$I$29,MATCH($E11,Products!$A$2:$A$29,0)) -> 1 bottle | T11: =IF(H11="Yes",Config!$B$5,"") -> 75 | U11: =INDEX(Products!$J$2:$J$29,MATCH($E11,Products!$A$2:$A$29,0)) -> No | V11: SIMULATED - proposed campus health-supply program
A12: INV-011 | B12: L01 | C12: =INDEX(Locations!$B$2:$B$9,MATCH($B12,Locations!$A$2:$A$9,0)) -> The Atrium | D12: =INDEX(Locations!$C$2:$C$9,MATCH($B12,Locations!$A$2:$A$9,0)) -> College Avenue | E12: P11 | F12: =INDEX(Products!$B$2:$B$29,MATCH($E12,Products!$A$2:$A$29,0)) -> Claritin | G12: =INDEX(Products!$C$2:$C$29,MATCH($E12,Products!$A$2:$A$29,0)) -> Allergy | H12: Yes | I12: Available | J12: =IF(H12="No","-",IF(I12="Available","Good supply",IF(I12="Low stock","Few left",IF(I12="Out of stock","None",IF(I12="Temporarily unavailable","Unavailable","Unknown"))))) -> Good supply | K12: Verified student report | L12: 46308.597 | M12: =IF(L12="","",ROUND((Config!$B$2-L12)*1440,0)) -> 40 | N12: =IF(K12="Staff verified",Config!$B$4,IF(OR(K12="Authorized student verified",K12="Multiple student reports",K12="Single student report"),Config!$B$3,"")) | O12: =IF(H12="No","n/a",IF(L12="","Unverified Data",IF(M12>N12,"Stale report",K12))) -> Verified student report | P12: =IF(AND(H12="Yes",OR(I12="Available",I12="Low stock")),IF(O12="Stale report","Verify first","Yes"),"No") -> Yes | Q12: =IF(H12="Yes","proposed_pending_approval","n/a") -> proposed_pending_approval | R12: =IF(H12="Yes","Retail swipe (proposed) / RU Express / Cash or card","n/a") -> Retail swipe (proposed) / RU Express / Cash or card | S12: =INDEX(Products!$I$2:$I$29,MATCH($E12,Products!$A$2:$A$29,0)) -> 1 package | T12: =IF(H12="Yes",Config!$B$5,"") -> 75 | U12: =INDEX(Products!$J$2:$J$29,MATCH($E12,Products!$A$2:$A$29,0)) -> No | V12: SIMULATED - proposed campus health-supply program
A13: INV-012 | B13: L01 | C13: =INDEX(Locations!$B$2:$B$9,MATCH($B13,Locations!$A$2:$A$9,0)) -> The Atrium | D13: =INDEX(Locations!$C$2:$C$9,MATCH($B13,Locations!$A$2:$A$9,0)) -> College Avenue | E13: P12 | F13: =INDEX(Products!$B$2:$B$29,MATCH($E13,Products!$A$2:$A$29,0)) -> Zyrtec | G13: =INDEX(Products!$C$2:$C$29,MATCH($E13,Products!$A$2:$A$29,0)) -> Allergy | H13: Yes | I13: Available | J13: =IF(H13="No","-",IF(I13="Available","Good supply",IF(I13="Low stock","Few left",IF(I13="Out of stock","None",IF(I13="Temporarily unavailable","Unavailable","Unknown"))))) -> Good supply | K13: Unverified Data | M13: =IF(L13="","",ROUND((Config!$B$2-L13)*1440,0)) | N13: =IF(K13="Staff verified",Config!$B$4,IF(OR(K13="Authorized student verified",K13="Multiple student reports",K13="Single student report"),Config!$B$3,"")) | O13: =IF(H13="No","n/a",IF(L13="","Unverified Data",IF(M13>N13,"Stale report",K13))) -> Unverified Data | P13: =IF(AND(H13="Yes",OR(I13="Available",I13="Low stock")),IF(O13="Stale report","Verify first","Yes"),"No") -> Yes | Q13: =IF(H13="Yes","proposed_pending_approval","n/a") -> proposed_pending_approval | R13: =IF(H13="Yes","Retail swipe (proposed) / RU Express / Cash or card","n/a") -> Retail swipe (proposed) / RU Express / Cash or card | S13: =INDEX(Products!$I$2:$I$29,MATCH($E13,Products!$A$2:$A$29,0)) -> 1 package | T13: =IF(H13="Yes",Config!$B$5,"") -> 75 | U13: =INDEX(Products!$J$2:$J$29,MATCH($E13,Products!$A$2:$A$29,0)) -> No | V13: SIMULATED - proposed campus health-supply program
A14: INV-013 | B14: L01 | C14: =INDEX(Locations!$B$2:$B$9,MATCH($B14,Locations!$A$2:$A$9,0)) -> The Atrium | D14: =INDEX(Locations!$C$2:$C$9,MATCH($B14,Locations!$A$2:$A$9,0)) -> College Avenue | E14: P13 | F14: =INDEX(Products!$B$2:$B$29,MATCH($E14,Products!$A$2:$A$29,0)) -> Benadryl | G14: =INDEX(Products!$C$2:$C$29,MATCH($E14,Products!$A$2:$A$29,0)) -> Allergy | H14: Yes | I14: Low stock | J14: =IF(H14="No","-",IF(I14="Available","Good supply",IF(I14="Low stock","Few left",IF(I14="Out of stock","None",IF(I14="Temporarily unavailable","Unavailable","Unknown"))))) -> Few left | K14: Unverified Data | M14: =IF(L14="","",ROUND((Config!$B$2-L14)*1440,0)) | N14: =IF(K14="Staff verified",Config!$B$4,IF(OR(K14="Authorized student verified",K14="Multiple student reports",K14="Single student report"),Config!$B$3,"")) | O14: =IF(H14="No","n/a",IF(L14="","Unverified Data",IF(M14>N14,"Stale report",K14))) -> Unverified Data | P14: =IF(AND(H14="Yes",OR(I14="Available",I14="Low stock")),IF(O14="Stale report","Verify first","Yes"),"No") -> Yes | Q14: =IF(H14="Yes","proposed_pending_approval","n/a") -> proposed_pending_approval | R14: =IF(H14="Yes","Retail swipe (proposed) / RU Express / Cash or card","n/a") -> Retail swipe (proposed) / RU Express / Cash or card | S14: =INDEX(Products!$I$2:$I$29,MATCH($E14,Products!$A$2:$A$29,0)) -> 1 package | T14: =IF(H14="Yes",Config!$B$5,"") -> 75 | U14: =INDEX(Products!$J$2:$J$29,MATCH($E14,Products!$A$2:$A$29,0)) -> No | V14: SIMULATED - proposed campus health-supply program
A15: INV-014 | B15: L01 | C15: =INDEX(Locations!$B$2:$B$9,MATCH($B15,Locations!$A$2:$A$9,0)) -> The Atrium | D15: =INDEX(Locations!$C$2:$C$9,MATCH($B15,Locations!$A$2:$A$9,0)) -> College Avenue | E15: P14 | F15: =INDEX(Products!$B$2:$B$29,MATCH($E15,Products!$A$2:$A$29,0)) -> Tums | G15: =INDEX(Products!$C$2:$C$29,MATCH($E15,Products!$A$2:$A$29,0)) -> Digestive | H15: Yes | I15: Low stock | J15: =IF(H15="No","-",IF(I15="Available","Good supply",IF(I15="Low stock","Few left",IF(I15="Out of stock","None",IF(I15="Temporarily unavailable","Unavailable","Unknown"))))) -> Few left | K15: Verified student report | L15: 46308.598 | M15: =IF(L15="","",ROUND((Config!$B$2-L15)*1440,0)) -> 39 | N15: =IF(K15="Staff verified",Config!$B$4,IF(OR(K15="Authorized student verified",K15="Multiple student reports",K15="Single student report"),Config!$B$3,"")) | O15: =IF(H15="No","n/a",IF(L15="","Unverified Data",IF(M15>N15,"Stale report",K15))) -> Verified student report | P15: =IF(AND(H15="Yes",OR(I15="Available",I15="Low stock")),IF(O15="Stale report","Verify first","Yes"),"No") -> Yes | Q15: =IF(H15="Yes","proposed_pending_approval","n/a") -> proposed_pending_approval | R15: =IF(H15="Yes","Retail swipe (proposed) / RU Express / Cash or card","n/a") -> Retail swipe (proposed) / RU Express / Cash or card | S15: =INDEX(Products!$I$2:$I$29,MATCH($E15,Products!$A$2:$A$29,0)) -> 1 package | T15: =IF(H15="Yes",Config!$B$5,"") -> 75 | U15: =INDEX(Products!$J$2:$J$29,MATCH($E15,Products!$A$2:$A$29,0)) -> No | V15: SIMULATED - proposed campus health-supply program
A16: INV-015 | B16: L01 | C16: =INDEX(Locations!$B$2:$B$9,MATCH($B16,Locations!$A$2:$A$9,0)) -> The Atrium | D16: =INDEX(Locations!$C$2:$C$9,MATCH($B16,Locations!$A$2:$A$9,0)) -> College Avenue | E16: P15 | F16: =INDEX(Products!$B$2:$B$29,MATCH($E16,Products!$A$2:$A$29,0)) -> Pepto-Bismol | G16: =INDEX(Products!$C$2:$C$29,MATCH($E16,Products!$A$2:$A$29,0)) -> Digestive | H16: Yes | I16: Unknown | J16: =IF(H16="No","-",IF(I16="Available","Good supply",IF(I16="Low stock","Few left",IF(I16="Out of stock","None",IF(I16="Temporarily unavailable","Unavailable","Unknown"))))) -> Unknown | K16: Unverified Data | M16: =IF(L16="","",ROUND((Config!$B$2-L16)*1440,0)) | N16: =IF(K16="Staff verified",Config!$B$4,IF(OR(K16="Authorized student verified",K16="Multiple student reports",K16="Single student report"),Config!$B$3,"")) | O16: =IF(H16="No","n/a",IF(L16="","Unverified Data",IF(M16>N16,"Stale report",K16))) -> Unverified Data | P16: =IF(AND(H16="Yes",OR(I16="Available",I16="Low stock")),IF(O16="Stale report","Verify first","Yes"),"No") -> No | Q16: =IF(H16="Yes","proposed_pending_approval","n/a") -> proposed_pending_approval | R16: =IF(H16="Yes","Retail swipe (proposed) / RU Express / Cash or card","n/a") -> Retail swipe (proposed) / RU Express / Cash or card | S16: =INDEX(Products!$I$2:$I$29,MATCH($E16,Products!$A$2:$A$29,0)) -> 1 package | T16: =IF(H16="Yes",Config!$B$5,"") -> 75 | U16: =INDEX(Products!$J$2:$J$29,MATCH($E16,Products!$A$2:$A$29,0)) -> No | V16: SIMULATED - proposed campus health-supply program
A17: INV-016 | B17: L01 | C17: =INDEX(Locations!$B$2:$B$9,MATCH($B17,Locations!$A$2:$A$9,0)) -> The Atrium | D17: =INDEX(Locations!$C$2:$C$9,MATCH($B17,Locations!$A$2:$A$9,0)) -> College Avenue | E17: P16 | F17: =INDEX(Products!$B$2:$B$29,MATCH($E17,Products!$A$2:$A$29,0)) -> Imodium A-D | G17: =INDEX(Products!$C$2:$C$29,MATCH($E17,Products!$A$2:$A$29,0)) -> Digestive | H17: Yes | I17: Available | J17: =IF(H17="No","-",IF(I17="Available","Good supply",IF(I17="Low stock","Few left",IF(I17="Out of stock","None",IF(I17="Temporarily unavailable","Unavailable","Unknown"))))) -> Good supply | K17: Verified student report | L17: 46308.598 | M17: =IF(L17="","",ROUND((Config!$B$2-L17)*1440,0)) -> 39 | N17: =IF(K17="Staff verified",Config!$B$4,IF(OR(K17="Authorized student verified",K17="Multiple student reports",K17="Single student report"),Config!$B$3,"")) | O17: =IF(H17="No","n/a",IF(L17="","Unverified Data",IF(M17>N17,"Stale report",K17))) -> Verified student report | P17: =IF(AND(H17="Yes",OR(I17="Available",I17="Low stock")),IF(O17="Stale report","Verify first","Yes"),"No") -> Yes | Q17: =IF(H17="Yes","proposed_pending_approval","n/a") -> proposed_pending_approval | R17: =IF(H17="Yes","Retail swipe (proposed) / RU Express / Cash or card","n/a") -> Retail swipe (proposed) / RU Express / Cash or card | S17: =INDEX(Products!$I$2:$I$29,MATCH($E17,Products!$A$2:$A$29,0)) -> 1 package | T17: =IF(H17="Yes",Config!$B$5,"") -> 75 | U17: =INDEX(Products!$J$2:$J$29,MATCH($E17,Products!$A$2:$A$29,0)) -> No | V17: SIMULATED - proposed campus health-supply program
A18: INV-017 | B18: L01 | C18: =INDEX(Locations!$B$2:$B$9,MATCH($B18,Locations!$A$2:$A$9,0)) -> The Atrium | D18: =INDEX(Locations!$C$2:$C$9,MATCH($B18,Locations!$A$2:$A$9,0)) -> College Avenue | E18: P17 | F18: =INDEX(Products!$B$2:$B$29,MATCH($E18,Products!$A$2:$A$29,0)) -> Pedialyte | G18: =INDEX(Products!$C$2:$C$29,MATCH($E18,Products!$A$2:$A$29,0)) -> Hydration | H18: Yes | I18: Out of stock | J18: =IF(H18="No","-",IF(I18="Available","Good supply",IF(I18="Low stock","Few left",IF(I18="Out of stock","None",IF(I18="Temporarily unavailable","Unavailable","Unknown"))))) -> None | K18: Staff verified | L18: 46308.49 | M18: =IF(L18="","",ROUND((Config!$B$2-L18)*1440,0)) -> 194 | N18: =IF(K18="Staff verified",Config!$B$4,IF(OR(K18="Authorized student verified",K18="Multiple student reports",K18="Single student report"),Config!$B$3,"")) -> 240 | O18: =IF(H18="No","n/a",IF(L18="","Unverified Data",IF(M18>N18,"Stale report",K18))) -> Staff verified | P18: =IF(AND(H18="Yes",OR(I18="Available",I18="Low stock")),IF(O18="Stale report","Verify first","Yes"),"No") -> No | Q18: =IF(H18="Yes","proposed_pending_approval","n/a") -> proposed_pending_approval | R18: =IF(H18="Yes","Retail swipe (proposed) / RU Express / Cash or card","n/a") -> Retail swipe (proposed) / RU Express / Cash or card | S18: =INDEX(Products!$I$2:$I$29,MATCH($E18,Products!$A$2:$A$29,0)) -> 2 bottles | T18: =IF(H18="Yes",Config!$B$5,"") -> 75 | U18: =INDEX(Products!$J$2:$J$29,MATCH($E18,Products!$A$2:$A$29,0)) -> No | V18: SIMULATED - proposed campus health-supply program
A19: INV-018 | B19: L01 | C19: =INDEX(Locations!$B$2:$B$9,MATCH($B19,Locations!$A$2:$A$9,0)) -> The Atrium | D19: =INDEX(Locations!$C$2:$C$9,MATCH($B19,Locations!$A$2:$A$9,0)) -> College Avenue | E19: P18 | F19: =INDEX(Products!$B$2:$B$29,MATCH($E19,Products!$A$2:$A$29,0)) -> Digital thermometer (brand varies) | G19: =INDEX(Products!$C$2:$C$29,MATCH($E19,Products!$A$2:$A$29,0)) -> Diagnostics | H19: Yes | I19: Available | J19: =IF(H19="No","-",IF(I19="Available","Good supply",IF(I19="Low stock","Few left",IF(I19="Out of stock","None",IF(I19="Temporarily unavailable","Unavailable","Unknown"))))) -> Good supply | K19: Verified student report | L19: 46308.603 | M19: =IF(L19="","",ROUND((Config!$B$2-L19)*1440,0)) -> 32 | N19: =IF(K19="Staff verified",Config!$B$4,IF(OR(K19="Authorized student verified",K19="Multiple student reports",K19="Single student report"),Config!$B$3,"")) | O19: =IF(H19="No","n/a",IF(L19="","Unverified Data",IF(M19>N19,"Stale report",K19))) -> Verified student report | P19: =IF(AND(H19="Yes",OR(I19="Available",I19="Low stock")),IF(O19="Stale report","Verify first","Yes"),"No") -> Yes | Q19: =IF(H19="Yes","proposed_pending_approval","n/a") -> proposed_pending_approval | R19: =IF(H19="Yes","Retail swipe (proposed) / RU Express / Cash or card","n/a") -> Retail swipe (proposed) / RU Express / Cash or card | S19: =INDEX(Products!$I$2:$I$29,MATCH($E19,Products!$A$2:$A$29,0)) -> 1 unit | T19: =IF(H19="Yes",Config!$B$5,"") -> 75 | U19: =INDEX(Products!$J$2:$J$29,MATCH($E19,Products!$A$2:$A$29,0)) -> No | V19: SIMULATED - proposed campus health-supply program
A20: INV-019 | B20: L01 | C20: =INDEX(Locations!$B$2:$B$9,MATCH($B20,Locations!$A$2:$A$9,0)) -> The Atrium | D20: =INDEX(Locations!$C$2:$C$9,MATCH($B20,Locations!$A$2:$A$9,0)) -> College Avenue | E20: P19 | F20: =INDEX(Products!$B$2:$B$29,MATCH($E20,Products!$A$2:$A$29,0)) -> iHealth COVID-19 Antigen Rapid Test | G20: =INDEX(Products!$C$2:$C$29,MATCH($E20,Products!$A$2:$A$29,0)) -> Diagnostics | H20: Yes | I20: Out of stock | J20: =IF(H20="No","-",IF(I20="Available","Good supply",IF(I20="Low stock","Few left",IF(I20="Out of stock","None",IF(I20="Temporarily unavailable","Unavailable","Unknown"))))) -> None | K20: Verified student report | L20: 46308.596 | M20: =IF(L20="","",ROUND((Config!$B$2-L20)*1440,0)) -> 42 | N20: =IF(K20="Staff verified",Config!$B$4,IF(OR(K20="Authorized student verified",K20="Multiple student reports",K20="Single student report"),Config!$B$3,"")) | O20: =IF(H20="No","n/a",IF(L20="","Unverified Data",IF(M20>N20,"Stale report",K20))) -> Verified student report | P20: =IF(AND(H20="Yes",OR(I20="Available",I20="Low stock")),IF(O20="Stale report","Verify first","Yes"),"No") -> No | Q20: =IF(H20="Yes","proposed_pending_approval","n/a") -> proposed_pending_approval | R20: =IF(H20="Yes","Retail swipe (proposed) / RU Express / Cash or card","n/a") -> Retail swipe (proposed) / RU Express / Cash or card | S20: =INDEX(Products!$I$2:$I$29,MATCH($E20,Products!$A$2:$A$29,0)) -> 1 kit | T20: =IF(H20="Yes",Config!$B$5,"") -> 75 | U20: =INDEX(Products!$J$2:$J$29,MATCH($E20,Products!$A$2:$A$29,0)) -> No | V20: SIMULATED - proposed campus health-supply program
A21: INV-020 | B21: L01 | C21: =INDEX(Locations!$B$2:$B$9,MATCH($B21,Locations!$A$2:$A$9,0)) -> The Atrium | D21: =INDEX(Locations!$C$2:$C$9,MATCH($B21,Locations!$A$2:$A$9,0)) -> College Avenue | E21: P20 | F21: =INDEX(Products!$B$2:$B$29,MATCH($E21,Products!$A$2:$A$29,0)) -> Band-Aid Brand Adhesive Bandages | G21: =INDEX(Products!$C$2:$C$29,MATCH($E21,Products!$A$2:$A$29,0)) -> First aid & comfort | H21: Yes | I21: Available | J21: =IF(H21="No","-",IF(I21="Available","Good supply",IF(I21="Low stock","Few left",IF(I21="Out of stock","None",IF(I21="Temporarily unavailable","Unavailable","Unknown"))))) -> Good supply | K21: Verified student report | L21: 46308.619 | M21: =IF(L21="","",ROUND((Config!$B$2-L21)*1440,0)) -> 9 | N21: =IF(K21="Staff verified",Config!$B$4,IF(OR(K21="Authorized student verified",K21="Multiple student reports",K21="Single student report"),Config!$B$3,"")) | O21: =IF(H21="No","n/a",IF(L21="","Unverified Data",IF(M21>N21,"Stale report",K21))) -> Verified student report | P21: =IF(AND(H21="Yes",OR(I21="Available",I21="Low stock")),IF(O21="Stale report","Verify first","Yes"),"No") -> Yes | Q21: =IF(H21="Yes","proposed_pending_approval","n/a") -> proposed_pending_approval | R21: =IF(H21="Yes","Retail swipe (proposed) / RU Express / Cash or card","n/a") -> Retail swipe (proposed) / RU Express / Cash or card | S21: =INDEX(Products!$I$2:$I$29,MATCH($E21,Products!$A$2:$A$29,0)) -> 1 box | T21: =IF(H21="Yes",Config!$B$5,"") -> 75 | U21: =INDEX(Products!$J$2:$J$29,MATCH($E21,Products!$A$2:$A$29,0)) -> No | V21: SIMULATED - proposed campus health-supply program
A22: INV-021 | B22: L01 | C22: =INDEX(Locations!$B$2:$B$9,MATCH($B22,Locations!$A$2:$A$9,0)) -> The Atrium | D22: =INDEX(Locations!$C$2:$C$9,MATCH($B22,Locations!$A$2:$A$9,0)) -> College Avenue | E22: P21 | F22: =INDEX(Products!$B$2:$B$29,MATCH($E22,Products!$A$2:$A$29,0)) -> Johnson & Johnson First Aid To Go Kit | G22: =INDEX(Products!$C$2:$C$29,MATCH($E22,Products!$A$2:$A$29,0)) -> First aid & comfort | H22: Yes | I22: Out of stock | J22: =IF(H22="No","-",IF(I22="Available","Good supply",IF(I22="Low stock","Few left",IF(I22="Out of stock","None",IF(I22="Temporarily unavailable","Unavailable","Unknown"))))) -> None | K22: Staff verified | L22: 46308.613 | M22: =IF(L22="","",ROUND((Config!$B$2-L22)*1440,0)) -> 17 | N22: =IF(K22="Staff verified",Config!$B$4,IF(OR(K22="Authorized student verified",K22="Multiple student reports",K22="Single student report"),Config!$B$3,"")) -> 240 | O22: =IF(H22="No","n/a",IF(L22="","Unverified Data",IF(M22>N22,"Stale report",K22))) -> Staff verified | P22: =IF(AND(H22="Yes",OR(I22="Available",I22="Low stock")),IF(O22="Stale report","Verify first","Yes"),"No") -> No | Q22: =IF(H22="Yes","proposed_pending_approval","n/a") -> proposed_pending_approval | R22: =IF(H22="Yes","Retail swipe (proposed) / RU Express / Cash or card","n/a") -> Retail swipe (proposed) / RU Express / Cash or card | S22: =INDEX(Products!$I$2:$I$29,MATCH($E22,Products!$A$2:$A$29,0)) -> 1 kit | T22: =IF(H22="Yes",Config!$B$5,"") -> 75 | U22: =INDEX(Products!$J$2:$J$29,MATCH($E22,Products!$A$2:$A$29,0)) -> No | V22: SIMULATED - proposed campus health-supply program
A23: INV-022 | B23: L01 | C23: =INDEX(Locations!$B$2:$B$9,MATCH($B23,Locations!$A$2:$A$9,0)) -> The Atrium | D23: =INDEX(Locations!$C$2:$C$9,MATCH($B23,Locations!$A$2:$A$9,0)) -> College Avenue | E23: P22 | F23: =INDEX(Products!$B$2:$B$29,MATCH($E23,Products!$A$2:$A$29,0)) -> Neosporin Original Ointment | G23: =INDEX(Products!$C$2:$C$29,MATCH($E23,Products!$A$2:$A$29,0)) -> First aid & comfort | H23: Yes | I23: Available | J23: =IF(H23="No","-",IF(I23="Available","Good supply",IF(I23="Low stock","Few left",IF(I23="Out of stock","None",IF(I23="Temporarily unavailable","Unavailable","Unknown"))))) -> Good supply | K23: Staff verified | L23: 46308.572 | M23: =IF(L23="","",ROUND((Config!$B$2-L23)*1440,0)) -> 76 | N23: =IF(K23="Staff verified",Config!$B$4,IF(OR(K23="Authorized student verified",K23="Multiple student reports",K23="Single student report"),Config!$B$3,"")) -> 240 | O23: =IF(H23="No","n/a",IF(L23="","Unverified Data",IF(M23>N23,"Stale report",K23))) -> Staff verified | P23: =IF(AND(H23="Yes",OR(I23="Available",I23="Low stock")),IF(O23="Stale report","Verify first","Yes"),"No") -> Yes | Q23: =IF(H23="Yes","proposed_pending_approval","n/a") -> proposed_pending_approval | R23: =IF(H23="Yes","Retail swipe (proposed) / RU Express / Cash or card","n/a") -> Retail swipe (proposed) / RU Express / Cash or card | S23: =INDEX(Products!$I$2:$I$29,MATCH($E23,Products!$A$2:$A$29,0)) -> 1 tube | T23: =IF(H23="Yes",Config!$B$5,"") -> 75 | U23: =INDEX(Products!$J$2:$J$29,MATCH($E23,Products!$A$2:$A$29,0)) -> No | V23: SIMULATED - proposed campus health-supply program
A24: INV-023 | B24: L01 | C24: =INDEX(Locations!$B$2:$B$9,MATCH($B24,Locations!$A$2:$A$9,0)) -> The Atrium | D24: =INDEX(Locations!$C$2:$C$9,MATCH($B24,Locations!$A$2:$A$9,0)) -> College Avenue | E24: P23 | F24: =INDEX(Products!$B$2:$B$29,MATCH($E24,Products!$A$2:$A$29,0)) -> Instant cold pack (brand varies) | G24: =INDEX(Products!$C$2:$C$29,MATCH($E24,Products!$A$2:$A$29,0)) -> First aid & comfort | H24: Yes | I24: Low stock | J24: =IF(H24="No","-",IF(I24="Available","Good supply",IF(I24="Low stock","Few left",IF(I24="Out of stock","None",IF(I24="Temporarily unavailable","Unavailable","Unknown"))))) -> Few left | K24: Staff verified | L24: 46308.496 | M24: =IF(L24="","",ROUND((Config!$B$2-L24)*1440,0)) -> 186 | N24: =IF(K24="Staff verified",Config!$B$4,IF(OR(K24="Authorized student verified",K24="Multiple student reports",K24="Single student report"),Config!$B$3,"")) -> 240 | O24: =IF(H24="No","n/a",IF(L24="","Unverified Data",IF(M24>N24,"Stale report",K24))) -> Staff verified | P24: =IF(AND(H24="Yes",OR(I24="Available",I24="Low stock")),IF(O24="Stale report","Verify first","Yes"),"No") -> Yes | Q24: =IF(H24="Yes","proposed_pending_approval","n/a") -> proposed_pending_approval | R24: =IF(H24="Yes","Retail swipe (proposed) / RU Express / Cash or card","n/a") -> Retail swipe (proposed) / RU Express / Cash or card | S24: =INDEX(Products!$I$2:$I$29,MATCH($E24,Products!$A$2:$A$29,0)) -> 1 pack | T24: =IF(H24="Yes",Config!$B$5,"") -> 75 | U24: =INDEX(Products!$J$2:$J$29,MATCH($E24,Products!$A$2:$A$29,0)) -> No | V24: SIMULATED - proposed campus health-supply program
A25: INV-024 | B25: L01 | C25: =INDEX(Locations!$B$2:$B$9,MATCH($B25,Locations!$A$2:$A$9,0)) -> The Atrium | D25: =INDEX(Locations!$C$2:$C$9,MATCH($B25,Locations!$A$2:$A$9,0)) -> College Avenue | E25: P24 | F25: =INDEX(Products!$B$2:$B$29,MATCH($E25,Products!$A$2:$A$29,0)) -> ThermaCare Heat Wrap | G25: =INDEX(Products!$C$2:$C$29,MATCH($E25,Products!$A$2:$A$29,0)) -> First aid & comfort | H25: Yes | I25: Unknown | J25: =IF(H25="No","-",IF(I25="Available","Good supply",IF(I25="Low stock","Few left",IF(I25="Out of stock","None",IF(I25="Temporarily unavailable","Unavailable","Unknown"))))) -> Unknown | K25: Unverified Data | M25: =IF(L25="","",ROUND((Config!$B$2-L25)*1440,0)) | N25: =IF(K25="Staff verified",Config!$B$4,IF(OR(K25="Authorized student verified",K25="Multiple student reports",K25="Single student report"),Config!$B$3,"")) | O25: =IF(H25="No","n/a",IF(L25="","Unverified Data",IF(M25>N25,"Stale report",K25))) -> Unverified Data | P25: =IF(AND(H25="Yes",OR(I25="Available",I25="Low stock")),IF(O25="Stale report","Verify first","Yes"),"No") -> No | Q25: =IF(H25="Yes","proposed_pending_approval","n/a") -> proposed_pending_approval | R25: =IF(H25="Yes","Retail swipe (proposed) / RU Express / Cash or card","n/a") -> Retail swipe (proposed) / RU Express / Cash or card | S25: =INDEX(Products!$I$2:$I$29,MATCH($E25,Products!$A$2:$A$29,0)) -> 1 package | T25: =IF(H25="Yes",Config!$B$5,"") -> 75 | U25: =INDEX(Products!$J$2:$J$29,MATCH($E25,Products!$A$2:$A$29,0)) -> No | V25: SIMULATED - proposed campus health-supply program
A26: INV-025 | B26: L01 | C26: =INDEX(Locations!$B$2:$B$9,MATCH($B26,Locations!$A$2:$A$9,0)) -> The Atrium | D26: =INDEX(Locations!$C$2:$C$9,MATCH($B26,Locations!$A$2:$A$9,0)) -> College Avenue | E26: P25 | F26: =INDEX(Products!$B$2:$B$29,MATCH($E26,Products!$A$2:$A$29,0)) -> Always Ultra Thin Pads | G26: =INDEX(Products!$C$2:$C$29,MATCH($E26,Products!$A$2:$A$29,0)) -> Menstrual & hygiene | H26: Yes | I26: Unknown | J26: =IF(H26="No","-",IF(I26="Available","Good supply",IF(I26="Low stock","Few left",IF(I26="Out of stock","None",IF(I26="Temporarily unavailable","Unavailable","Unknown"))))) -> Unknown | K26: Unverified Data | M26: =IF(L26="","",ROUND((Config!$B$2-L26)*1440,0)) | N26: =IF(K26="Staff verified",Config!$B$4,IF(OR(K26="Authorized student verified",K26="Multiple student reports",K26="Single student report"),Config!$B$3,"")) | O26: =IF(H26="No","n/a",IF(L26="","Unverified Data",IF(M26>N26,"Stale report",K26))) -> Unverified Data | P26: =IF(AND(H26="Yes",OR(I26="Available",I26="Low stock")),IF(O26="Stale report","Verify first","Yes"),"No") -> No | Q26: =IF(H26="Yes","proposed_pending_approval","n/a") -> proposed_pending_approval | R26: =IF(H26="Yes","Retail swipe (proposed) / RU Express / Cash or card","n/a") -> Retail swipe (proposed) / RU Express / Cash or card | S26: =INDEX(Products!$I$2:$I$29,MATCH($E26,Products!$A$2:$A$29,0)) -> 1 package | T26: =IF(H26="Yes",Config!$B$5,"") -> 75 | U26: =INDEX(Products!$J$2:$J$29,MATCH($E26,Products!$A$2:$A$29,0)) -> No | V26: SIMULATED - proposed campus health-supply program
A27: INV-026 | B27: L01 | C27: =INDEX(Locations!$B$2:$B$9,MATCH($B27,Locations!$A$2:$A$9,0)) -> The Atrium | D27: =INDEX(Locations!$C$2:$C$9,MATCH($B27,Locations!$A$2:$A$9,0)) -> College Avenue | E27: P26 | F27: =INDEX(Products!$B$2:$B$29,MATCH($E27,Products!$A$2:$A$29,0)) -> Tampax Pearl Tampons | G27: =INDEX(Products!$C$2:$C$29,MATCH($E27,Products!$A$2:$A$29,0)) -> Menstrual & hygiene | H27: Yes | I27: Available | J27: =IF(H27="No","-",IF(I27="Available","Good supply",IF(I27="Low stock","Few left",IF(I27="Out of stock","None",IF(I27="Temporarily unavailable","Unavailable","Unknown"))))) -> Good supply | K27: Verified student report | L27: 46308.597 | M27: =IF(L27="","",ROUND((Config!$B$2-L27)*1440,0)) -> 40 | N27: =IF(K27="Staff verified",Config!$B$4,IF(OR(K27="Authorized student verified",K27="Multiple student reports",K27="Single student report"),Config!$B$3,"")) | O27: =IF(H27="No","n/a",IF(L27="","Unverified Data",IF(M27>N27,"Stale report",K27))) -> Verified student report | P27: =IF(AND(H27="Yes",OR(I27="Available",I27="Low stock")),IF(O27="Stale report","Verify first","Yes"),"No") -> Yes | Q27: =IF(H27="Yes","proposed_pending_approval","n/a") -> proposed_pending_approval | R27: =IF(H27="Yes","Retail swipe (proposed) / RU Express / Cash or card","n/a") -> Retail swipe (proposed) / RU Express / Cash or card | S27: =INDEX(Products!$I$2:$I$29,MATCH($E27,Products!$A$2:$A$29,0)) -> 1 package | T27: =IF(H27="Yes",Config!$B$5,"") -> 75 | U27: =INDEX(Products!$J$2:$J$29,MATCH($E27,Products!$A$2:$A$29,0)) -> No | V27: SIMULATED - proposed campus health-supply program
A28: INV-027 | B28: L01 | C28: =INDEX(Locations!$B$2:$B$9,MATCH($B28,Locations!$A$2:$A$9,0)) -> The Atrium | D28: =INDEX(Locations!$C$2:$C$9,MATCH($B28,Locations!$A$2:$A$9,0)) -> College Avenue | E28: P27 | F28: =INDEX(Products!$B$2:$B$29,MATCH($E28,Products!$A$2:$A$29,0)) -> Purell Advanced Hand Sanitizer | G28: =INDEX(Products!$C$2:$C$29,MATCH($E28,Products!$A$2:$A$29,0)) -> Menstrual & hygiene | H28: Yes | I28: Available | J28: =IF(H28="No","-",IF(I28="Available","Good supply",IF(I28="Low stock","Few left",IF(I28="Out of stock","None",IF(I28="Temporarily unavailable","Unavailable","Unknown"))))) -> Good supply | K28: Staff verified | L28: 46308.612 | M28: =IF(L28="","",ROUND((Config!$B$2-L28)*1440,0)) -> 19 | N28: =IF(K28="Staff verified",Config!$B$4,IF(OR(K28="Authorized student verified",K28="Multiple student reports",K28="Single student report"),Config!$B$3,"")) -> 240 | O28: =IF(H28="No","n/a",IF(L28="","Unverified Data",IF(M28>N28,"Stale report",K28))) -> Staff verified | P28: =IF(AND(H28="Yes",OR(I28="Available",I28="Low stock")),IF(O28="Stale report","Verify first","Yes"),"No") -> Yes | Q28: =IF(H28="Yes","proposed_pending_approval","n/a") -> proposed_pending_approval | R28: =IF(H28="Yes","Retail swipe (proposed) / RU Express / Cash or card","n/a") -> Retail swipe (proposed) / RU Express / Cash or card | S28: =INDEX(Products!$I$2:$I$29,MATCH($E28,Products!$A$2:$A$29,0)) -> 1 bottle | T28: =IF(H28="Yes",Config!$B$5,"") -> 75 | U28: =INDEX(Products!$J$2:$J$29,MATCH($E28,Products!$A$2:$A$29,0)) -> No | V28: SIMULATED - proposed campus health-supply program
A29: INV-028 | B29: L01 | C29: =INDEX(Locations!$B$2:$B$9,MATCH($B29,Locations!$A$2:$A$9,0)) -> The Atrium | D29: =INDEX(Locations!$C$2:$C$9,MATCH($B29,Locations!$A$2:$A$9,0)) -> College Avenue | E29: P28 | F29: =INDEX(Products!$B$2:$B$29,MATCH($E29,Products!$A$2:$A$29,0)) -> Disposable face masks (brand varies) | G29: =INDEX(Products!$C$2:$C$29,MATCH($E29,Products!$A$2:$A$29,0)) -> Menstrual & hygiene | H29: Yes | I29: Available | J29: =IF(H29="No","-",IF(I29="Available","Good supply",IF(I29="Low stock","Few left",IF(I29="Out of stock","None",IF(I29="Temporarily unavailable","Unavailable","Unknown"))))) -> Good supply | K29: Staff verified | L29: 46308.428 | M29: =IF(L29="","",ROUND((Config!$B$2-L29)*1440,0)) -> 283 | N29: =IF(K29="Staff verified",Config!$B$4,IF(OR(K29="Authorized student verified",K29="Multiple student reports",K29="Single student report"),Config!$B$3,"")) -> 240 | O29: =IF(H29="No","n/a",IF(L29="","Unverified Data",IF(M29>N29,"Stale report",K29))) -> Stale report | P29: =IF(AND(H29="Yes",OR(I29="Available",I29="Low stock")),IF(O29="Stale report","Verify first","Yes"),"No") -> Verify first | Q29: =IF(H29="Yes","proposed_pending_approval","n/a") -> proposed_pending_approval | R29: =IF(H29="Yes","Retail swipe (proposed) / RU Express / Cash or card","n/a") -> Retail swipe (proposed) / RU Express / Cash or card | S29: =INDEX(Products!$I$2:$I$29,MATCH($E29,Products!$A$2:$A$29,0)) -> 1 pack | T29: =IF(H29="Yes",Config!$B$5,"") -> 75 | U29: =INDEX(Products!$J$2:$J$29,MATCH($E29,Products!$A$2:$A$29,0)) -> No | V29: SIMULATED - proposed campus health-supply program
